Workbook

Sheet LEGGIMI
A1: 🏙️ Il costo della vita nelle province italiane – Analisi Excel
A2: Progetto di Francesco Autorino – Data Analyst
A4: 📌 I fogli
A5: Controllo → controlli automatici: devono essere tutti ✅
A6: Riepilogo → i numeri chiave
A7: Confronto → ⭐ scegli 2 province dai menu a tendina e confrontale
A8: Calcolatore → ⭐ scrivi il tuo reddito: quanti anni di risparmio per una casa
A9: Province → le 107 province con gli indicatori calcolati (filtri, colori dal verde al rosso)
A10: Zone → Nord, Centro, Sud e Isole a confronto, con 3 grafici
A11: Andamento → redditi e case anno per anno, con l'inflazione
A12: Dati_Redditi / Dati_Case → i dati per anno (tabelle Excel con filtri)
A14: 🎨 Legenda dei colori
... A21: Inflazione: ISTAT, indice NIC

Sheet Controllo
A1: ✅ Controlli automatici
A3: Controllo | B3: Atteso | C3: Trovato | D3: Esito
A4: Province nel foglio Province | B4: 107 | C4: =COUNTA(Province!$A$5:$A$111) -> 107 | D4: =IF(C4=B4,"✅ OK","❌ Errore") -> ✅ OK
A5: Righe di redditi (107 province × 9 anni, meno le province sarde mancanti) | B5: 962 | C5: =COUNTA(Dati_Redditi!$B$2:$B$963) -> 962 | D5: =IF(C5=B5,"✅ OK","❌ Errore") -> ✅ OK
A6: Righe di case | B6: 1060 | C6: =COUNTA(Dati_Case!$B$2:$B$1061) -> 1060 | D6: =IF(C6=B6,"✅ OK","❌ Errore") -> ✅ OK
A7: Province per zona = 107 | B7: 107 | C7: =Zone!B9 -> 107 | D7: =IF(C7=B7,"✅ OK","❌ Errore") -> ✅ OK
A8: Province senza prezzo della casa | B8: 1 | C8: =COUNTBLANK(Province!$G$5:$G$111) -> 1 | D8: =IF(C8=B8,"✅ OK","❌ Errore") -> ✅ OK
A9: Errori nelle formule degli anni di reddito | B9: 0 | C9: =SUMPRODUCT(--ISERROR(Province!$K$5:$K$111)) -> 0 | D9: =IF(C9=B9,"✅ OK","❌ Errore") -> ✅ OK
A10: Nessun reddito sotto i 10.000 € | B10: 0 | C10: =COUNTIF(Province!$E$5:$E$111,"<10000") -> 0 | D10: =IF(C10=B10,"✅ OK","❌ Errore") -> ✅ OK

Sheet Riepilogo
A1: 🏙️ Il costo della vita nelle province – numeri chiave
A2: Tutte le celle sono formule sul foglio Province.
A3: Indicatore | B3: Valore
A4: Province analizzate | B4: =COUNTA(Province!$A$5:$A$111) -> 107
A5: Reddito medio di una provincia tipo (mediana, €) | B5: =MEDIAN(Province!$E$5:$E$111) -> 24470
A6: Provincia con il reddito più alto | B6: =INDEX(Province!$B$5:$B$111,MATCH(MAX(Province!$E$5:$E$111),Province!$E$5:$E$111,0)) -> Milano
A7: Provincia con il reddito più basso | B7: =INDEX(Province!$B$5:$B$111,MATCH(MIN(Province!$E$5:$E$111),Province!$E$5:$E$111,0)) -> Ragusa
A8: Prezzo della casa in una provincia tipo (mediana, €/m²) | B8: =MEDIAN(Province!$G$5:$G$111) -> 1185
A9: Provincia con le case più care | B9: =INDEX(Province!$B$5:$B$111,MATCH(MAX(Province!$G$5:$G$111),Province!$G$5:$G$111,0)) -> Milano
A10: Anni di reddito per una casa (mediana) | B10: =MEDIAN(Province!$K$5:$K$111) -> 3.8121448
A11: Dove la casa è più facile da comprare | B11: =INDEX(Province!$B$5:$B$111,MATCH(MIN(Province!$K$5:$K$111),Province!$K$5:$K$111,0)) -> Biella
A12: Dove la casa è più difficile da comprare | B12: =INDEX(Province!$B$5:$B$111,MATCH(MAX(Province!$K$5:$K$111),Province!$K$5:$K$111,0)) -> Bolzano
A13: Pieno da 50 litri in % del reddito di un mese (mediana) | B13: =MEDIAN(Province!$M$5:$M$111) -> 0.049838611
A14: Crescita dei redditi 2016-2024 (mediana) | B14: =MEDIAN(Province!$N$5:$N$111) -> 0.20632736
A15: Crescita dei prezzi delle case 2016-2024 (mediana) | B15: =MEDIAN(Province!$O$5:$O$111) -> -0.032355555
A16: Inflazione 2016-2024 (ISTAT) | B16: =Andamento!F13/Andamento!F5-1 -> 0.209

Sheet Confronto
A1: ⚖️ Confronta due province
A2: Scegli due province dai menu a tendina (celle gialle).
A4: Provincia | B4: Milano | C4: Napoli | D4: Differenza
A5: Zona | B5: =IFERROR(INDEX(Province!$D$5:$D$111,MATCH($B$4,Province!$B$5:$B$111,0)),"") -> Nord | C5: =IFERROR(INDEX(Province!$D$5:$D$111,MATCH($C$4,Province!$B$5:$B$111,0)),"") -> Sud
A6: Reddito medio 2024 (€) | B6: =IFERROR(INDEX(Province!$E$5:$E$111,MATCH($B$4,Province!$B$5:$B$111,0)),"") -> 33959 | C6: =IFERROR(INDEX(Province!$E$5:$E$111,MATCH($C$4,Province!$B$5:$B$111,0)),"") -> 21968 | D6: =IFERROR(C6-B6,"") -> -11991
A7: Prezzo casa 2025 (€/m²) | B7: =IFERROR(INDEX(Province!$G$5:$G$111,MATCH($B$4,Province!$B$5:$B$111,0)),"") -> 3604 | C7: =IFERROR(INDEX(Province!$G$5:$G$111,MATCH($C$4,Province!$B$5:$B$111,0)),"") -> 1698 | D7: =IFERROR(C7-B7,"") -> -1906
A8: Casa da 80 m² (€) | B8: =IFERROR(INDEX(Province!$J$5:$J$111,MATCH($B$4,Province!$B$5:$B$111,0)),"") -> 288320 | C8: =IFERROR(INDEX(Province!$J$5:$J$111,MATCH($C$4,Province!$B$5:$B$111,0)),"") -> 135840
A9: Anni di reddito per la casa | B9: =IFERROR(INDEX(Province!$K$5:$K$111,MATCH($B$4,Province!$B$5:$B$111,0)),"") -> 8.4902382 | C9: =IFERROR(INDEX(Province!$K$5:$K$111,MATCH($C$4,Province!$B$5:$B$111,0)),"") -> 6.1835397 | D9: =IFERROR(C9-B9,"") -> -2.3066985
A10: Benzina self (€/l) | B10: =IFERROR(INDEX(Province!$I$5:$I$111,MATCH($B$4,Province!$B$5:$B$111,0)),"") -> 2.018 | C10: =IFERROR(INDEX(Province!$I$5:$I$111,MATCH($C$4,Province!$B$5:$B$111,0)),"") -> 2.053
A11: Pieno in % del reddito di un mese | B11: =IFERROR(INDEX(Province!$M$5:$M$111,MATCH($B$4,Province!$B$5:$B$111,0)),"") -> 0.03565476 | C11: =IFERROR(INDEX(Province!$M$5:$M$111,MATCH($C$4,Province!$B$5:$B$111,0)),"") -> 0.056072469 | D11: =IFERROR(C11-B11,"") -> 0.020417709
A12: Crescita reddito 2016-24 | B12: =IFERROR(INDEX(Province!$N$5:$N$111,MATCH($B$4,Province!$B$5:$B$111,0)),"") -> 0.19033264 | C12: =IFERROR(INDEX(Province!$N$5:$N$111,MATCH($C$4,Province!$B$5:$B$111,0)),"") -> 0.19560248
A13: Crescita casa 2016-24 | B13: =IFERROR(INDEX(Province!$O$5:$O$111,MATCH($B$4,Province!$B$5:$B$111,0)),"") -> 0.27794449 | C13: =IFERROR(INDEX(Province!$O$5:$O$111,MATCH($C$4,Province!$B$5:$B$111,0)),"") -> -0.019197208
A14: Posizione per la casa (1 = più facile) | B14: =IFERROR(INDEX(Province!$P$5:$P$111,MATCH($B$4,Province!$B$5:$B$111,0)),"") -> 103 | C14: =IFERROR(INDEX(Province!$P$5:$P$111,MATCH($C$4,Province!$B$5:$B$111,0)),"") -> 95 | D14: =IFERROR(C14-B14,"") -> -8

Sheet Calcolatore
A1: 🧮 Il mio calcolatore
A2: Scrivi nelle celle gialle il tuo reddito e la casa che vuoi: vedi quanti anni servono in ogni provincia.
A4: Il mio reddito lordo annuo (€) | B4: 25000
A5: Metri quadri della casa | B5: 80
A6: Quanto risparmio all'anno (%) | B6: 0.2
A8: Anni di risparmio per comprare casa, per zona
A9: Zona | B9: Prezzo medio casa (€) | C9: Anni di reddito | D9: Anni di risparmio
A10: Nord | B10: =Zone!D5*$B$5 -> 119703.83 | C10: =B10/$B$4 -> 4.7881532 | D10: =B10/($B$4*$B$6) -> 23.940766
A11: Centro | B11: =Zone!D6*$B$5 -> 115429.09 | C11: =B11/$B$4 -> 4.6171636 | D11: =B11/($B$4*$B$6) -> 23.085818
A12: Sud | B12: =Zone!D7*$B$5 -> 71230 | C12: =B12/$B$4 -> 2.8492 | D12: =B12/($B$4*$B$6) -> 14.246
A13: Isole | B13: =Zone!D8*$B$5 -> 73698.462 | C13: =B13/$B$4 -> 2.9479385 | D13: =B13/($B$4*$B$6) -> 14.739692
A15: Le 5 province dove servono meno anni
A16: Posto | B16: Provincia | C16: Prezzo casa (€) | D16: Anni di risparmio
A17: 1 | B17: =INDEX(Province!$B$5:$B$111,MATCH(SMALL(Province!$G$5:$G$111,A17),Province!$G$5:$G$111,0)) -> Caltanissetta | C17: =SMALL(Province!$G$5:$G$111,A17)*$B$5 -> 41440 | D17: =C17/($B$4*$B$6) -> 8.288
A18: 2 | B18: =INDEX(Province!$B$5:$B$111,MATCH(SMALL(Province!$G$5:$G$111,A18),Province!$G$5:$G$111,0)) -> Isernia | C18: =SMALL(Province!$G$5:$G$111,A18)*$B$5 -> 44880 | D18: =C18/($B$4*$B$6) -> 8.976
A19: 3 | B19: =INDEX(Province!$B$5:$B$111,MATCH(SMALL(Province!$G$5:$G$111,A19),Province!$G$5:$G$111,0)) -> Biella | C19: =SMALL(Province!$G$5:$G$111,A19)*$B$5 -> 45600 | D19: =C19/($B$4*$B$6) -> 9.12
A20: 4 | B20: =INDEX(Province!$B$5:$B$111,MATCH(SMALL(Province!$G$5:$G$111,A20),Province!$G$5:$G$111,0)) -> Agrigento | C20: =SMALL(Province!$G$5:$G$111,A20)*$B$5 -> 46480 | D20: =C20/($B$4*$B$6) -> 9.296
A21: 5 | B21: =INDEX(Province!$B$5:$B$111,MATCH(SMALL(Province!$G$5:$G$111,A21),Province!$G$5:$G$111,0)) -> Vibo Valentia | C21: =SMALL(Province!$G$5:$G$111,A21)*$B$5 -> 47280 | D21: =C21/($B$4*$B$6) -> 9.456

Sheet Province
A1: 🏙️ Le 107 province: dati e indicatori
A2: Testo blu = dato · Testo nero = formula. Metri quadri della casa e litri del pieno: celle gialle. | M2: m² casa | N2: 80 | O2: litri pieno | P2: 50
A4: Sigla | B4: Provincia | C4: Regione | D4: Zona | E4: Reddito medio 2024 (€) | F4: Reddito 2016 (€) | G4: Prezzo casa 2025 (€/m²) | H4: Prezzo casa 2016 (€/m²) | I4: Benzina self (€/l) | J4: Casa (€) | K4: Anni di reddito per la casa | L4: Pieno (€) | M4: Pieno in % reddito di un mese | N4: Crescita reddito 2016-24 | O4: Crescita casa 2016-24 | P4: Posizione per la casa (1 = più facile)
A5: AG | B5: Agrigento | C5: Sicilia | D5: Isole | E5: 18162 | F5: 14386 | G5: 581 | H5: 662 | I5: 2.055 | J5: =IF(G5="","",G5*$N$2) -> 46480 | K5: =IF(G5="","",J5/E5) -> 2.5591895 | L5: =I5*$P$2 -> 102.75 | M5: =L5/(E5/12) -> 0.067888999 | N5: =IF(F5="","",E5/F5-1) -> 0.26247741 | O5: =IFERROR(SUMIFS(Dati_Case!$E$2:$E$1061,Dati_Case!$B$2:$B$1061,A5,Dati_Case!$A$2:$A$1061,2024)/H5-1,"") -> -0.12990937 | P5: =IF(K5="","",RANK(K5,$K$5:$K$111,1)) -> 7
A6: AL | B6: Alessandria | C6: Piemonte | D6: Nord | E6: 25157 | F6: 21243 | G6: 756 | H6: 894 | I6: 2.023 | J6: =IF(G6="","",G6*$N$2) -> 60480 | K6: =IF(G6="","",J6/E6) -> 2.4041022 | L6: =I6*$P$2 -> 101.15 | M6: =L6/(E6/12) -> 0.048248996 | N6: =IF(F6="","",E6/F6-1) -> 0.18424893 | O6: =IFERROR(SUMIFS(Dati_Case!$E$2:$E$1061,Dati_Case!$B$2:$B$1061,A6,Dati_Case!$A$2:$A$1061,2024)/H6-1,"") -> -0.13646532 | P6: =IF(K6="","",RANK(K6,$K$5:$K$111,1)) -> 5
A7: AN | B7: Ancona | C7: Marche | D7: Centro | E7: 24788 | F7: 21104 | G7: 1123 | H7: 1245 | I7: 2.022 | J7: =IF(G7="","",G7*$N$2) -> 89840 | K7: =IF(G7="","",J7/E7) -> 3.6243344 | L7: =I7*$P$2 -> 101.1 | M7: =L7/(E7/12) -> 0.048943037 | N7: =IF(F7="","",E7/F7-1) -> 0.17456406 | O7: =IFERROR(SUMIFS(Dati_Case!$E$2:$E$1061,Dati_Case!$B$2:$B$1061,A7,Dati_Case!$A$2:$A$1061,2024)/H7-1,"") -> -0.10441767 | P7: =IF(K7="","",RANK(K7,$K$5:$K$111,1)) -> 47
A8: AO | B8: Aosta | C8: Valle d'Aosta | D8: Nord | E8: 26873 | F8: 22285 | G8: 1903 | H8: 1852 | I8: 2.033 | J8: =IF(G8="","",G8*$N$2) -> 152240 | K8: =IF(G8="","",J8/E8) -> 5.6651658 | L8: =I8*$P$2 -> 101.65 | M8: =L8/(E8/12) -> 0.045391285 | N8: =IF(F8="","",E8/F8-1) -> 0.20587839 | O8: =IFERROR(SUMIFS(Dati_Case!$E$2:$E$1061,Dati_Case!$B$2:$B$1061,A8,Dati_Case!$A$2:$A$1061,2024)/H8-1,"") -> 0.023758099 | P8: =IF(K8="","",RANK(K8,$K$5:$K$111,1)) -> 89
A9: AR | B9: Arezzo | C9: Toscana | D9: Centro | E9: 24475 | F9: 20354 | G9: 1340 | H9: 1322 | I9: 2.033 | J9: =IF(G9="","",G9*$N$2) -> 107200 | K9: =IF(G9="","",J9/E9) -> 4.3799796 | L9: =I9*$P$2 -> 101.65 | M9: =L9/(E9/12) -> 0.049838611 | N9: =IF(F9="","",E9/F9-1) -> 0.20246635 | O9: =IFERROR(SUMIFS(Dati_Case!$E$2:$E$1061,Dati_Case!$B$2:$B$1061,A9,Dati_Case!$A$2:$A$1061,2024)/H9-1,"") -> 0.0037821483 | P9: =IF(K9="","",RANK(K9,$K$5:$K$111,1)) -> 65
A10: AP | B10: Ascoli Piceno | C10: Marche | D10: Centro | E10: 23404 | F10: 18497 | G10: 1499 | H10: 1376 | I10: 2.037 | J10: =IF(G10="","",G10*$N$2) -> 119920 | K10: =IF(G10="","",J10/E10) -> 5.1239104 | L10: =I10*$P$2 -> 101.85 | M10: =L10/(E10/12) -> 0.052221842 | N10: =IF(F10="","",E10/F10-1) -> 0.26528626 | O10: =IFERROR(SUMIFS(Dati_Case!$E$2:$E$1061,Dati_Case!$B$2:$B$1061,A10,Dati_Case!$A$2:$A$1061,2024)/H10-1,"") -> 0.074127907 | P10: =IF(K10="","",RANK(K10,$K$5:$K$111,1)) -> 82
A11: AT | B11: Asti | C11: Piemonte | D11: Nord | E11: 24299 | F11: 20415 | G11: 690 | H11: 789 | I11: 2.022 | J11: =IF(G11="","",G11*$N$2) -> 55200 | K11: =IF(G11="","",J11/E11) -> 2.2716984 | L11: =I11*$P$2 -> 101.1 | M11: =L11/(E11/12) -> 0.049927981 | N11: =IF(F11="","",E11/F11-1) -> 0.19025227 | O11: =IFERROR(SUMIFS(Dati_Case!$E$2:$E$1061,Dati_Case!$B$2:$B$1061,A11,Dati_Case!$A$2:$A$1061,2024)/H11-1,"") -> -0.12294043 | P11: =IF(K11="","",RANK(K11,$K$5:$K$111,1)) -> 4
A12: AV | B12: Avellino | C12: Campania | D12: Sud | E12: 19885 | F12: 16030 | G12: 713 | H12: 761 | I12: 2.072 | J12: =IF(G12="","",G12*$N$2) -> 57040 | K12: =IF(G12="","",J12/E12) -> 2.8684938 | L12: =I12*$P$2 -> 103.6 | M12: =L12/(E12/12) -> 0.062519487 | N12: =IF(F12="","",E12/F12-1) -> 0.24048659 | O12: =IFERROR(SUMIFS(Dati_Case!$E$2:$E$1061,Dati_Case!$B$2:$B$1061,A12,Dati_Case!$A$2:$A$1061,2024)/H12-1,"") -> -0.05913272 | P12: =IF(K12="","",RANK(K12,$K$5:$K$111,1)) -> 17
A13: BA | B13: Bari | C13: Puglia | D13: Sud | E13: 21920 | F13: 17752 | G13: 1306 | H13: 1326 | I13: 2.021 | J13: =IF(G13="","",G13*$N$2) -> 104480 | K13: =IF(G13="","",J13/E13) -> 4.7664234 | L13: =I13*$P$2 -> 101.05 | M13: =L13/(E13/12) -> 0.055319343 | N13: =IF(F13="","",E13/F13-1) -> 0.23479045 | O13: =IFERROR(SUMIFS(Dati_Case!$E$2:$E$1061,Dati_Case!$B$2:$B$1061,A13,Dati_Case!$A$2:$A$1061,2024)/H13-1,"") -> -0.015082956 | P13: =IF(K13="","",RANK(K13,$K$5:$K$111,1)) -> 77
A14: BT | B14: Barletta-Andria-Trani | C14: Puglia | D14: Sud | E14: 18139 | F14: 14930 | G14: 1217 | I14: 2.031 | J14: =IF(G14="","",G14*$N$2) -> 97360 | K14: =IF(G14="","",J14/E14) -> 5.3674403 | L14: =I14*$P$2 -> 101.55 | M14: =L14/(E14/12) -> 0.067181212 | N14: =IF(F14="","",E14/F14-1) -> 0.21493637 | O14: =IFERROR(SUMIFS(Dati_Case!$E$2:$E$1061,Dati_Case!$B$2:$B$1061,A14,Dati_Case!$A$2:$A$1061,2024)/H14-1,"") | P14: =IF(K14="","",RANK(K14,$K$5:$K$111,1)) -> 87
A15: BL | B15: Belluno | C15: Veneto | D15: Nord | E15: 25439 | F15: 21132 | G15: 1102 | H15: 1464 | I15: 2.04 | J15: =IF(G15="","",G15*$N$2) -> 88160 | K15: =IF(G15="","",J15/E15) -> 3.465545 | L15: =I15*$P$2 -> 102 | M15: =L15/(E15/12) -> 0.048115099 | N15: =IF(F15="","",E15/F15-1) -> 0.20381412 | O15: =IFERROR(SUMIFS(Dati_Case!$E$2:$E$1061,Dati_Case!$B$2:$B$1061,A15,Dati_Case!$A$2:$A$1061,2024)/H15-1,"") -> -0.2568306 | P15: =IF(K15="","",RANK(K15,$K$5:$K$111,1)) -> 42
A16: BN | B16: Benevento | C16: Campania | D16: Sud | E16: 19327 | F16: 15452 | G16: 795 | H16: 1187 | I16: 2.065 | J16: =IF(G16="","",G16*$N$2) -> 63600 | K16: =IF(G16="","",J16/E16) -> 3.2907332 | L16: =I16*$P$2 -> 103.25 | M16: =L16/(E16/12) -> 0.064107208 | N16: =IF(F16="","",E16/F16-1) -> 0.2507766 | O16: =IFERROR(SUMIFS(Dati_Case!$E$2:$E$1061,Dati_Case!$B$2:$B$1061,A16,Dati_Case!$A$2:$A$1061,2024)/H16-1,"") -> -0.31508003 | P16: =IF(K16="","",RANK(K16,$K$5:$K$111,1)) -> 36
A17: BG | B17: Bergamo | C17: Lombardia | D17: Nord | E17: 27399 | F17: 22942 | G17: 1264 | H17: 1210 | I17: 2.028 | J17: =IF(G17="","",G17*$N$2) -> 101120 | K17: =IF(G17="","",J17/E17) -> 3.6906456 | L17: =I17*$P$2 -> 101.4 | M17: =L17/(E17/12) -> 0.04441038 | N17: =IF(F17="","",E17/F17-1) -> 0.19427251 | O17: =IFERROR(SUMIFS(Dati_Case!$E$2:$E$1061,Dati_Case!$B$2:$B$1061,A17,Dati_Case!$A$2:$A$1061,2024)/H17-1,"") -> 0.037190083 | P17: =IF(K17="","",RANK(K17,$K$5:$K$111,1)) -> 50
A18: BI | B18: Biella | C18: Piemonte | D18: Nord | E18: 25135 | F18: 21524 | G18: 570 | H18: 658 | I18: 2.025 | J18: =IF(G18="","",G18*$N$2) -> 45600 | K18: =IF(G18="","",J18/E18) -> 1.8142033 | L18: =I18*$P$2 -> 101.25 | M18: =L18/(E18/12) -> 0.04833897 | N18: =IF(F18="","",E18/F18-1) -> 0.16776621 | O18: =IFERROR(SUMIFS(Dati_Case!$E$2:$E$1061,Dati_Case!$B$2:$B$1061,A18,Dati_Case!$A$2:$A$1061,2024)/H18-1,"") -> -0.13221884 | P18: =IF(K18="","",RANK(K18,$K$5:$K$111,1)) -> 1
A19: BO | B19: Bologna | C19: Emilia-Romagna | D19: Nord | E19: 29784 | F19: 25526 | G19: 2222 | H19: 2080 | I19: 2.032 | J19: =IF(G19="","",G19*$N$2) -> 177760 | K19: =IF(G19="","",J19/E19) -> 5.9683051 | L19: =I19*$P$2 -> 101.6 | M19: =L19/(E19/12) -> 0.04093473 | N19: =IF(F19="","",E19/F19-1) -> 0.16681031 | O19: =IFERROR(SUMIFS(Dati_Case!$E$2:$E$1061,Dati_Case!$B$2:$B$1061,A19,Dati_Case!$A$2:$A$1061,2024)/H19-1,"") -> 0.041346154 | P19: =IF(K19="","",RANK(K19,$K$5:$K$111,1)) -> 93
A20: BZ | B20: Bolzano | C20: Trentino-Alto Adige | D20: Nord | E20: 28351 | F20: 23505 | G20: 3249 | H20: 2810 | I20: 2.059 | J20: =IF(G20="","",G20*$N$2) -> 259920 | K20: =IF(G20="","",J20/E20) -> 9.1679306 | L20: =I20*$P$2 -> 102.95 | M20: =L20/(E20/12) -> 0.043575183 | N20: =IF(F20="","",E20/F20-1) -> 0.2061689 | O20: =IFERROR(SUMIFS(Dati_Case!$E$2:$E$1061,Dati_Case!$B$2:$B$1061,A20,Dati_Case!$A$2:$A$1061,2024)/H20-1,"") -> 0.11530249 | P20: =IF(K20="","",RANK(K20,$K$5:$K$111,1)) -> 106
A21: BS | B21: Brescia | C21: Lombardia | D21: Nord | E21: 26559 | F21: 22027 | G21: 1548 | H21: 1532 | I21: 2.035 | J21: =IF(G21="","",G21*$N$2) -> 123840 | K21: =IF(G21="","",J21/E21) -> 4.6628262 | L21: =I21*$P$2 -> 101.75 | M21: =L21/(E21/12) -> 0.045973116 | N21: =IF(F21="","",E21/F21-1) -> 0.20574749 | O21: =IFERROR(SUMIFS(Dati_Case!$E$2:$E$1061,Dati_Case!$B$2:$B$1061,A21,Dati_Case!$A$2:$A$1061,2024)/H21-1,"") -> -0.0058746736 | P21: =IF(K21="","",RANK(K21,$K$5:$K$111,1)) -> 73
A22: BR | B22: Brindisi | C22: Puglia | D22: Sud | E22: 19504 | F22: 15929 | G22: 1074 | H22: 797 | I22: 2.051 | J22: =IF(G22="","",G22*$N$2) -> 85920 | K22: =IF(G22="","",J22/E22) -> 4.4052502 | L22: =I22*$P$2 -> 102.55 | M22: =L22/(E22/12) -> 0.06309475 | N22: =IF(F22="","",E22/F22-1) -> 0.22443342 | O22: =IFERROR(SUMIFS(Dati_Case!$E$2:$E$1061,Dati_Case!$B$2:$B$1061,A22,Dati_Case!$A$2:$A$1061,2024)/H22-1,"") -> 0.30740276 | P22: =IF(K22="","",RANK(K22,$K$5:$K$111,1)) -> 66
A23: CA | B23: Cagliari | C23: Sardegna | D23: Isole | E23: 25319 | G23: 1336 | H23: 1294 | I23: 2.014 | J23: =IF(G23="","",G23*$N$2) -> 106880 | K23: =IF(G23="","",J23/E23) -> 4.2213358 | L23: =I23*$P$2 -> 100.7 | M23: =L23/(E23/12) -> 0.047727003 | N23: =IF(F23="","",E23/F23-1) | O23: =IFERROR(SUMIFS(Dati_Case!$E$2:$E$1061,Dati_Case!$B$2:$B$1061,A23,Dati_Case!$A$2:$A$1061,2024)/H23-1,"") -> 0.0054095827 | P23: =IF(K23="","",RANK(K23,$K$5:$K$111,1)) -> 62
A24: CL | B24: Caltanissetta | C24: Sicilia | D24: Isole | E24: 19024 | F24: 15019 | G24: 518 | H24: 600 | I24: 2.053 | J24: =IF(G24="","",G24*$N$2) -> 41440 | K24: =IF(G24="","",J24/E24) -> 2.1783011 | L24: =I24*$P$2 -> 102.65 | M24: =L24/(E24/12) -> 0.06474979 | N24: =IF(F24="","",E24/F24-1) -> 0.26666223 | O24: =IFERROR(SUMIFS(Dati_Case!$E$2:$E$1061,Dati_Case!$B$2:$B$1061,A24,Dati_Case!$A$2:$A$1061,2024)/H24-1,"") -> -0.13333333 | P24: =IF(K24="","",RANK(K24,$K$5:$K$111,1)) -> 2
A25: CB | B25: Campobasso | C25: Molise | D25: Sud | E25: 19935 | F25: 16072 | G25: 699 | H25: 724 | I25: 2.037 | J25: =IF(G25="","",G25*$N$2) -> 55920 | K25: =IF(G25="","",J25/E25) -> 2.8051166 | L25: =I25*$P$2 -> 101.85 | M25: =L25/(E25/12) -> 0.061309255 | N25: =IF(F25="","",E25/F25-1) -> 0.2403559 | O25: =IFERROR(SUMIFS(Dati_Case!$E$2:$E$1061,Dati_Case!$B$2:$B$1061,A25,Dati_Case!$A$2:$A$1061,2024)/H25-1,"") -> -0.035911602 | P25: =IF(K25="","",RANK(K25,$K$5:$K$111,1)) -> 16
A26: CE | B26: Caserta | C26: Campania | D26: Sud | E26: 20306 | F26: 16371 | G26: 809 | H26: 791 | I26: 2.06 | J26: =IF(G26="","",G26*$N$2) -> 64720 | K26: =IF(G26="","",J26/E26) -> 3.1872353 | L26: =I26*$P$2 -> 103 | M26: =L26/(E26/12) -> 0.060868709 | N26: =IF(F26="","",E26/F26-1) -> 0.24036406 | O26: =IFERROR(SUMIFS(Dati_Case!$E$2:$E$1061,Dati_Case!$B$2:$B$1061,A26,Dati_Case!$A$2:$A$1061,2024)/H26-1,"") -> 0.01517067 | P26: =IF(K26="","",RANK(K26,$K$5:$K$111,1)) -> 31
A27: CT | B27: Catania | C27: Sicilia | D27: Isole | E27: 21019 | F27: 16968 | G27: 813 | H27: 958 | I27: 2.044 | J27: =IF(G27="","",G27*$N$2) -> 65040 | K27: =IF(G27="","",J27/E27) -> 3.0943432 | L27: =I27*$P$2 -> 102.2 | M27: =L27/(E27/12) -> 0.05834721 | N27: =IF(F27="","",E27/F27-1) -> 0.23874352 | O27: =IFERROR(SUMIFS(Dati_Case!$E$2:$E$1061,Dati_Case!$B$2:$B$1061,A27,Dati_Case!$A$2:$A$1061,2024)/H27-1,"") -> -0.1440501 | P27: =IF(K27="","",RANK(K27,$K$5:$K$111,1)) -> 27
A28: CZ | B28: Catanzaro | C28: Calabria | D28: Sud | E28: 19346 | F28: 16035 | G28: 772 | H28: 767 | I28: 2.069 | J28: =IF(G28="","",G28*$N$2) -> 61760 | K28: =IF(G28="","",J28/E28) -> 3.1923912 | L28: =I28*$P$2 -> 103.45 | M28: =L28/(E28/12) -> 0.064168304 | N28: =IF(F28="","",E28/F28-1) -> 0.20648581 | O28: =IFERROR(SUMIFS(Dati_Case!$E$2:$E$1061,Dati_Case!$B$2:$B$1061,A28,Dati_Case!$A$2:$A$1061,2024)/H28-1,"") -> -0.0026075619 | P28: =IF(K28="","",RANK(K28,$K$5:$K$111,1)) -> 32
A29: CH | B29: Chieti | C29: Abruzzo | D29: Sud | E29: 21427 | F29: 17439 | G29: 870 | H29: 725 | I29: 2.04 | J29: =IF(G29="","",G29*$N$2) -> 69600 | K29: =IF(G29="","",J29/E29) -> 3.2482382 | L29: =I29*$P$2 -> 102 | M29: =L29/(E29/12) -> 0.057124189 | N29: =IF(F29="","",E29/F29-1) -> 0.22868284 | O29: =IFERROR(SUMIFS(Dati_Case!$E$2:$E$1061,Dati_Case!$B$2:$B$1061,A29,Dati_Case!$A$2:$A$1061,2024)/H29-1,"") -> 0.18482759 | P29: =IF(K29="","",RANK(K29,$K$5:$K$111,1)) -> 34
A30: CO | B30: Como | C30: Lombardia | D30: Nord | E30: 27138 | F30: 23146 | G30: 1598 | H30: 1522 | I30: 2.014 | J30: =IF(G30="","",G30*$N$2) -> 127840 | K30: =IF(G30="","",J30/E30) -> 4.7107377 | L30: =I30*$P$2 -> 100.7 | M30: =L30/(E30/12) -> 0.044527968 | N30: =IF(F30="","",E30/F30-1) -> 0.17247041 | O30: =IFERROR(SUMIFS(Dati_Case!$E$2:$E$1061,Dati_Case!$B$2:$B$1061,A30,Dati_Case!$A$2:$A$1061,2024)/H30-1,"") -> 0.03088042 | P30: =IF(K30="","",RANK(K30,$K$5:$K$111,1)) -> 75
A31: CS | B31: Cosenza | C31: Calabria | D31: Sud | E31: 18263 | F31: 14693 | G31: 692 | H31: 708 | I31: 2.05 | J31: =IF(G31="","",G31*$N$2) -> 55360 | K31: =IF(G31="","",J31/E31) -> 3.0312654 | L31: =I31*$P$2 -> 102.5 | M31: =L31/(E31/12) -> 0.067349285 | N31: =IF(F31="","",E31/F31-1) -> 0.24297284 | O31: =IFERROR(SUMIFS(Dati_Case!$E$2:$E$1061,Dati_Case!$B$2:$B$1061,A31,Dati_Case!$A$2:$A$1061,2024)/H31-1,"") -> -0.024011299 | P31: =IF(K31="","",RANK(K31,$K$5:$K$111,1)) -> 25
A32: CR | B32: Cremona | C32: Lombardia | D32: Nord | E32: 26546 | F32: 22481 | G32: 957 | H32: 982 | I32: 2.026 | J32: =IF(G32="","",G32*$N$2) -> 76560 | K32: =IF(G32="","",J32/E32) -> 2.8840503 | L32: =I32*$P$2 -> 101.3 | M32: =L32/(E32/12) -> 0.04579221 | N32: =IF(F32="","",E32/F32-1) -> 0.18081936 | O32: =IFERROR(SUMIFS(Dati_Case!$E$2:$E$1061,Dati_Case!$B$2:$B$1061,A32,Dati_Case!$A$2:$A$1061,2024)/H32-1,"") -> -0.056008147 | P32: =IF(K32="","",RANK(K32,$K$5:$K$111,1)) -> 18
A33: KR | B33: Crotone | C33: Calabria | D33: Sud | E33: 17873 | F33: 13898 | G33: 666 | H33: 699 | I33: 2.067 | J33: =IF(G33="","",G33*$N$2) -> 53280 | K33: =IF(G33="","",J33/E33) -> 2.9810328 | L33: =I33*$P$2 -> 103.35 | M33: =L33/(E33/12) -> 0.069389582 | N33: =IF(F33="","",E33/F33-1) -> 0.28601238 | O33: =IFERROR(SUMIFS(Dati_Case!$E$2:$E$1061,Dati_Case!$B$2:$B$1061,A33,Dati_Case!$A$2:$A$1061,2024)/H33-1,"") -> -0.062947067 | P33: =IF(K33="","",RANK(K33,$K$5:$K$111,1)) -> 23
A34: CN | B34: Cuneo | C34: Piemonte | D34: Nord | E34: 25380 | F34: 21011 | G34: 994 | H34: 1096 | I34: 2.035 | J34: =IF(G34="","",G34*$N$2) -> 79520 | K34: =IF(G34="","",J34/E34) -> 3.1331757 | L34: =I34*$P$2 -> 101.75 | M34: =L34/(E34/12) -> 0.048108747 | N34: =IF(F34="","",E34/F34-1) -> 0.2079387 | O34: =IFERROR(SUMIFS(Dati_Case!$E$2:$E$1061,Dati_Case!$B$2:$B$1061,A34,Dati_Case!$A$2:$A$1061,2024)/H34-1,"") -> -0.073905109 | P34: =IF(K34="","",RANK(K34,$K$5:$K$111,1)) -> 29
A35: EN | B35: Enna | C35: Sicilia | D35: Isole | E35: 18556 | F35: 14418 | G35: 616 | H35: 818 | I35: 2.052 | J35: =IF(G35="","",G35*$N$2) -> 49280 | K35: =IF(G35="","",J35/E35) -> 2.6557448 | L35: =I35*$P$2 -> 102.6 | M35: =L35/(E35/12) -> 0.066350507 | N35: =IF(F35="","",E35/F35-1) -> 0.28700236 | O35: =IFERROR(SUMIFS(Dati_Case!$E$2:$E$1061,Dati_Case!$B$2:$B$1061,A35,Dati_Case!$A$2:$A$1061,2024)/H35-1,"") -> -0.24327628 | P35: =IF(K35="","",RANK(K35,$K$5:$K$111,1)) -> 10
... A64: NO | B64: Novara | C64: Piemonte | D64: Nord | E64: 26571 | F64: 23227 | G64: 1070 | H64: 946 | I64: 2.02 | J64: =IF(G64="","",G64*$N$2) -> 85600 | K64: =IF(G64="","",J64/E64) -> 3.2215573 | L64: =I64*$P$2 -> 101 | M64: =L64/(E64/12) -> 0.045613639 | N64: =IF(F64="","",E64/F64-1) -> 0.14397038 | O64: =IFERROR(SUMIFS(Dati_Case!$E$2:$E$1061,Dati_Case!$B$2:$B$1061,A64,Dati_Case!$A$2:$A$1061,2024)/H64-1,"") -> 0.094080338 | P64: =IF(K64="","",RANK(K64,$K$5:$K$111,1)) -> 33
A65: NU | B65: Nuoro | C65: Sardegna | D65: Isole | E65: 19642 | G65: 1235 | H65: 1226 | I65: 2.074 | J65: =IF(G65="","",G65*$N$2) -> 98800 | K65: =IF(G65="","",J65/E65) -> 5.0300377 | L65: =I65*$P$2 -> 103.7 | M65: =L65/(E65/12) -> 0.063354037 | N65: =IF(F65="","",E65/F65-1) | O65: =IFERROR(SUMIFS(Dati_Case!$E$2:$E$1061,Dati_Case!$B$2:$B$1061,A65,Dati_Case!$A$2:$A$1061,2024)/H65-1,"") -> -0.0097879282 | P65: =IF(K65="","",RANK(K65,$K$5:$K$111,1)) -> 79
A66: OR | B66: Oristano | C66: Sardegna | D66: Isole | E66: 19528 | G66: 729 | H66: 699 | I66: 2.03 | J66: =IF(G66="","",G66*$N$2) -> 58320 | K66: =IF(G66="","",J66/E66) -> 2.986481 | L66: =I66*$P$2 -> 101.5 | M66: =L66/(E66/12) -> 0.062371979 | N66: =IF(F66="","",E66/F66-1) | O66: =IFERROR(SUMIFS(Dati_Case!$E$2:$E$1061,Dati_Case!$B$2:$B$1061,A66,Dati_Case!$A$2:$A$1061,2024)/H66-1,"") -> 0.034334764 | P66: =IF(K66="","",RANK(K66,$K$5:$K$111,1)) -> 24
A67: PD | B67: Padova | C67: Veneto | D67: Nord | E67: 27623 | F67: 23044 | G67: 1249 | H67: 1291 | I67: 2.016 | J67: =IF(G67="","",G67*$N$2) -> 99920 | K67: =IF(G67="","",J67/E67) -> 3.6172755 | L67: =I67*$P$2 -> 100.8 | M67: =L67/(E67/12) -> 0.043789596 | N67: =IF(F67="","",E67/F67-1) -> 0.19870682 | O67: =IFERROR(SUMIFS(Dati_Case!$E$2:$E$1061,Dati_Case!$B$2:$B$1061,A67,Dati_Case!$A$2:$A$1061,2024)/H67-1,"") -> -0.035631294 | P67: =IF(K67="","",RANK(K67,$K$5:$K$111,1)) -> 46
A68: PA | B68: Palermo | C68: Sicilia | D68: Isole | E68: 21878 | F68: 17823 | G68: 938 | H68: 967 | I68: 2.027 | J68: =IF(G68="","",G68*$N$2) -> 75040 | K68: =IF(G68="","",J68/E68) -> 3.4299296 | L68: =I68*$P$2 -> 101.35 | M68: =L68/(E68/12) -> 0.055590091 | N68: =IF(F68="","",E68/F68-1) -> 0.22751501 | O68: =IFERROR(SUMIFS(Dati_Case!$E$2:$E$1061,Dati_Case!$B$2:$B$1061,A68,Dati_Case!$A$2:$A$1061,2024)/H68-1,"") -> -0.042399173 | P68: =IF(K68="","",RANK(K68,$K$5:$K$111,1)) -> 39
A69: PR | B69: Parma | C69: Emilia-Romagna | D69: Nord | E69: 29424 | F69: 24652 | G69: 1309 | H69: 1296 | I69: 2.029 | J69: =IF(G69="","",G69*$N$2) -> 104720 | K69: =IF(G69="","",J69/E69) -> 3.5589995 | L69: =I69*$P$2 -> 101.45 | M69: =L69/(E69/12) -> 0.041374388 | N69: =IF(F69="","",E69/F69-1) -> 0.19357456 | O69: =IFERROR(SUMIFS(Dati_Case!$E$2:$E$1061,Dati_Case!$B$2:$B$1061,A69,Dati_Case!$A$2:$A$1061,2024)/H69-1,"") -> -0.021604938 | P69: =IF(K69="","",RANK(K69,$K$5:$K$111,1)) -> 43
...

Sheet Zone
A1: 🗺️ Nord, Centro, Sud e Isole
A2: Media semplice delle province di ogni zona (formule AVERAGEIFS sul foglio Province).
A4: Zona | B4: Province | C4: Reddito medio (€) | D4: Prezzo casa (€/m²) | E4: Anni di reddito per la casa | F4: Pieno in % reddito mese
A5: Nord | B5: =COUNTIF(Province!$D$5:$D$111,A5) -> 47 | C5: =AVERAGEIFS(Province!$E$5:$E$111,Province!$D$5:$D$111,A5) -> 26490.468 | D5: =AVERAGEIFS(Province!$G$5:$G$111,Province!$D$5:$D$111,A5) -> 1496.2979 | E5: =AVERAGEIFS(Province!$K$5:$K$111,Province!$D$5:$D$111,A5) -> 4.5017672 | F5: =AVERAGEIFS(Province!$M$5:$M$111,Province!$D$5:$D$111,A5) -> 0.046199342
A6: Centro | B6: =COUNTIF(Province!$D$5:$D$111,A6) -> 22 | C6: =AVERAGEIFS(Province!$E$5:$E$111,Province!$D$5:$D$111,A6) -> 24323.909 | D6: =AVERAGEIFS(Province!$G$5:$G$111,Province!$D$5:$D$111,A6) -> 1442.8636 | E6: =AVERAGEIFS(Province!$K$5:$K$111,Province!$D$5:$D$111,A6) -> 4.7034117 | F6: =AVERAGEIFS(Province!$M$5:$M$111,Province!$D$5:$D$111,A6) -> 0.050338904
A7: Sud | B7: =COUNTIF(Province!$D$5:$D$111,A7) -> 24 | C7: =AVERAGEIFS(Province!$E$5:$E$111,Province!$D$5:$D$111,A7) -> 20050.542 | D7: =AVERAGEIFS(Province!$G$5:$G$111,Province!$D$5:$D$111,A7) -> 890.375 | E7: =AVERAGEIFS(Province!$K$5:$K$111,Province!$D$5:$D$111,A7) -> 3.5392107 | F7: =AVERAGEIFS(Province!$M$5:$M$111,Province!$D$5:$D$111,A7) -> 0.061794674
A8: Isole | B8: =COUNTIF(Province!$D$5:$D$111,A8) -> 14 | C8: =AVERAGEIFS(Province!$E$5:$E$111,Province!$D$5:$D$111,A8) -> 20126.071 | D8: =AVERAGEIFS(Province!$G$5:$G$111,Province!$D$5:$D$111,A8) -> 921.23077 | E8: =AVERAGEIFS(Province!$K$5:$K$111,Province!$D$5:$D$111,A8) -> 3.6142181 | F8: =AVERAGEIFS(Province!$M$5:$M$111,Province!$D$5:$D$111,A8) -> 0.061329608
A9: Italia | B9: =SUM(B5:B8) -> 107 | C9: =AVERAGE(Province!$E$5:$E$111) -> 23767.813 | D9: =AVERAGE(Province!$G$5:$G$111) -> 1277.4906 | E9: =AVERAGE(Province!$K$5:$K$111) -> 4.2168303 | F9: =AVERAGE(Province!$M$5:$M$111) -> 0.052528146

Sheet Andamento
A1: 📈 Redditi e case anno per anno
A2: Media delle province (AVERAGEIFS sui fogli Dati_Redditi e Dati_Case). Inflazione: ISTAT NIC.
A4: Anno | B4: Reddito Nord | C4: Reddito Centro | D4: Reddito Sud | E4: Reddito Isole | F4: Inflazione (2016=100)
A5: 2016 | B5: =AVERAGEIFS(Dati_Redditi!$F$2:$F$963,Dati_Redditi!$A$2:$A$963,$A5,Dati_Redditi!$D$2:$D$963,"Nord") -> 22297.447 | C5: =AVERAGEIFS(Dati_Redditi!$F$2:$F$963,Dati_Redditi!$A$2:$A$963,$A5,Dati_Redditi!$D$2:$D$963,"Centro") -> 20180.682 | D5: =AVERAGEIFS(Dati_Redditi!$F$2:$F$963,Dati_Redditi!$A$2:$A$963,$A5,Dati_Redditi!$D$2:$D$963,"Sud") -> 16200.125 | E5: =AVERAGEIFS(Dati_Redditi!$F$2:$F$963,Dati_Redditi!$A$2:$A$963,$A5,Dati_Redditi!$D$2:$D$963,"Isole") -> 16265.385 | F5: 100
A6: 2017 | B6: =AVERAGEIFS(Dati_Redditi!$F$2:$F$963,Dati_Redditi!$A$2:$A$963,$A6,Dati_Redditi!$D$2:$D$963,"Nord") -> 22411.957 | C6: =AVERAGEIFS(Dati_Redditi!$F$2:$F$963,Dati_Redditi!$A$2:$A$963,$A6,Dati_Redditi!$D$2:$D$963,"Centro") -> 20258.682 | D6: =AVERAGEIFS(Dati_Redditi!$F$2:$F$963,Dati_Redditi!$A$2:$A$963,$A6,Dati_Redditi!$D$2:$D$963,"Sud") -> 16250.5 | E6: =AVERAGEIFS(Dati_Redditi!$F$2:$F$963,Dati_Redditi!$A$2:$A$963,$A6,Dati_Redditi!$D$2:$D$963,"Isole") -> 16404.786 | F6: 101.2
A7: 2018 | B7: =AVERAGEIFS(Dati_Redditi!$F$2:$F$963,Dati_Redditi!$A$2:$A$963,$A7,Dati_Redditi!$D$2:$D$963,"Nord") -> 22917.34 | C7: =AVERAGEIFS(Dati_Redditi!$F$2:$F$963,Dati_Redditi!$A$2:$A$963,$A7,Dati_Redditi!$D$2:$D$963,"Centro") -> 20738.091 | D7: =AVERAGEIFS(Dati_Redditi!$F$2:$F$963,Dati_Redditi!$A$2:$A$963,$A7,Dati_Redditi!$D$2:$D$963,"Sud") -> 16607.708 | E7: =AVERAGEIFS(Dati_Redditi!$F$2:$F$963,Dati_Redditi!$A$2:$A$963,$A7,Dati_Redditi!$D$2:$D$963,"Isole") -> 16757.071 | F7: 102.3
A8: 2019 | B8: =AVERAGEIFS(Dati_Redditi!$F$2:$F$963,Dati_Redditi!$A$2:$A$963,$A8,Dati_Redditi!$D$2:$D$963,"Nord") -> 23062.149 | C8: =AVERAGEIFS(Dati_Redditi!$F$2:$F$963,Dati_Redditi!$A$2:$A$963,$A8,Dati_Redditi!$D$2:$D$963,"Centro") -> 20906.182 | D8: =AVERAGEIFS(Dati_Redditi!$F$2:$F$963,Dati_Redditi!$A$2:$A$963,$A8,Dati_Redditi!$D$2:$D$963,"Sud") -> 16760.833 | E8: =AVERAGEIFS(Dati_Redditi!$F$2:$F$963,Dati_Redditi!$A$2:$A$963,$A8,Dati_Redditi!$D$2:$D$963,"Isole") -> 16893.714 | F8: 102.9
A9: 2020 | B9: =AVERAGEIFS(Dati_Redditi!$F$2:$F$963,Dati_Redditi!$A$2:$A$963,$A9,Dati_Redditi!$D$2:$D$963,"Nord") -> 22762.213 | C9: =AVERAGEIFS(Dati_Redditi!$F$2:$F$963,Dati_Redditi!$A$2:$A$963,$A9,Dati_Redditi!$D$2:$D$963,"Centro") -> 20685.545 | D9: =AVERAGEIFS(Dati_Redditi!$F$2:$F$963,Dati_Redditi!$A$2:$A$963,$A9,Dati_Redditi!$D$2:$D$963,"Sud") -> 16793.833 | E9: =AVERAGEIFS(Dati_Redditi!$F$2:$F$963,Dati_Redditi!$A$2:$A$963,$A9,Dati_Redditi!$D$2:$D$963,"Isole") -> 16887.429 | F9: 102.8
A10: 2021 | B10: =AVERAGEIFS(Dati_Redditi!$F$2:$F$963,Dati_Redditi!$A$2:$A$963,$A10,Dati_Redditi!$D$2:$D$963,"Nord") -> 23816.021 | C10: =AVERAGEIFS(Dati_Redditi!$F$2:$F$963,Dati_Redditi!$A$2:$A$963,$A10,Dati_Redditi!$D$2:$D$963,"Centro") -> 21590.636 | D10: =AVERAGEIFS(Dati_Redditi!$F$2:$F$963,Dati_Redditi!$A$2:$A$963,$A10,Dati_Redditi!$D$2:$D$963,"Sud") -> 17514.958 | E10: =AVERAGEIFS(Dati_Redditi!$F$2:$F$963,Dati_Redditi!$A$2:$A$963,$A10,Dati_Redditi!$D$2:$D$963,"Isole") -> 17562.143 | F10: 104.8
A11: 2022 | B11: =AVERAGEIFS(Dati_Redditi!$F$2:$F$963,Dati_Redditi!$A$2:$A$963,$A11,Dati_Redditi!$D$2:$D$963,"Nord") -> 24968.766 | C11: =AVERAGEIFS(Dati_Redditi!$F$2:$F$963,Dati_Redditi!$A$2:$A$963,$A11,Dati_Redditi!$D$2:$D$963,"Centro") -> 22691.545 | D11: =AVERAGEIFS(Dati_Redditi!$F$2:$F$963,Dati_Redditi!$A$2:$A$963,$A11,Dati_Redditi!$D$2:$D$963,"Sud") -> 18429.333 | E11: =AVERAGEIFS(Dati_Redditi!$F$2:$F$963,Dati_Redditi!$A$2:$A$963,$A11,Dati_Redditi!$D$2:$D$963,"Isole") -> 18455.643 | F11: 113.4
A12: 2023 | B12: =AVERAGEIFS(Dati_Redditi!$F$2:$F$963,Dati_Redditi!$A$2:$A$963,$A12,Dati_Redditi!$D$2:$D$963,"Nord") -> 25525.553 | C12: =AVERAGEIFS(Dati_Redditi!$F$2:$F$963,Dati_Redditi!$A$2:$A$963,$A12,Dati_Redditi!$D$2:$D$963,"Centro") -> 23367.364 | D12: =AVERAGEIFS(Dati_Redditi!$F$2:$F$963,Dati_Redditi!$A$2:$A$963,$A12,Dati_Redditi!$D$2:$D$963,"Sud") -> 19194.042 | E12: =AVERAGEIFS(Dati_Redditi!$F$2:$F$963,Dati_Redditi!$A$2:$A$963,$A12,Dati_Redditi!$D$2:$D$963,"Isole") -> 19266.857 | F12: 119.7
A13: 2024 | B13: =AVERAGEIFS(Dati_Redditi!$F$2:$F$963,Dati_Redditi!$A$2:$A$963,$A13,Dati_Redditi!$D$2:$D$963,"Nord") -> 26490.468 | C13: =AVERAGEIFS(Dati_Redditi!$F$2:$F$963,Dati_Redditi!$A$2:$A$963,$A13,Dati_Redditi!$D$2:$D$963,"Centro") -> 24323.909 | D13: =AVERAGEIFS(Dati_Redditi!$F$2:$F$963,Dati_Redditi!$A$2:$A$963,$A13,Dati_Redditi!$D$2:$D$963,"Sud") -> 20050.542 | E13: =AVERAGEIFS(Dati_Redditi!$F$2:$F$963,Dati_Redditi!$A$2:$A$963,$A13,Dati_Redditi!$D$2:$D$963,"Isole") -> 20126.071 | F13: 120.9
A16: Anno | B16: Casa Nord (€/m²) | C16: Casa Centro (€/m²) | D16: Casa Sud (€/m²) | E16: Casa Isole (€/m²)
A17: 2016 | B17: =AVERAGEIFS(Dati_Case!$E$2:$E$1061,Dati_Case!$A$2:$A$1061,$A17,Dati_Case!$D$2:$D$1061,"Nord") -> 1485.1087 | C17: =AVERAGEIFS(Dati_Case!$E$2:$E$1061,Dati_Case!$A$2:$A$1061,$A17,Dati_Case!$D$2:$D$1061,"Centro") -> 1590.0909 | D17: =AVERAGEIFS(Dati_Case!$E$2:$E$1061,Dati_Case!$A$2:$A$1061,$A17,Dati_Case!$D$2:$D$1061,"Sud") -> 892.52174 | E17: =AVERAGEIFS(Dati_Case!$E$2:$E$1061,Dati_Case!$A$2:$A$1061,$A17,Dati_Case!$D$2:$D$1061,"Isole") -> 965.53846
A18: 2017 | B18: =AVERAGEIFS(Dati_Case!$E$2:$E$1061,Dati_Case!$A$2:$A$1061,$A18,Dati_Case!$D$2:$D$1061,"Nord") -> 1459.4468 | C18: =AVERAGEIFS(Dati_Case!$E$2:$E$1061,Dati_Case!$A$2:$A$1061,$A18,Dati_Case!$D$2:$D$1061,"Centro") -> 1545.4091 | D18: =AVERAGEIFS(Dati_Case!$E$2:$E$1061,Dati_Case!$A$2:$A$1061,$A18,Dati_Case!$D$2:$D$1061,"Sud") -> 897 | E18: =AVERAGEIFS(Dati_Case!$E$2:$E$1061,Dati_Case!$A$2:$A$1061,$A18,Dati_Case!$D$2:$D$1061,"Isole") -> 954.07692
A19: 2018 | B19: =AVERAGEIFS(Dati_Case!$E$2:$E$1061,Dati_Case!$A$2:$A$1061,$A19,Dati_Case!$D$2:$D$1061,"Nord") -> 1447.5106 | C19: =AVERAGEIFS(Dati_Case!$E$2:$E$1061,Dati_Case!$A$2:$A$1061,$A19,Dati_Case!$D$2:$D$1061,"Centro") -> 1509.9091 | D19: =AVERAGEIFS(Dati_Case!$E$2:$E$1061,Dati_Case!$A$2:$A$1061,$A19,Dati_Case!$D$2:$D$1061,"Sud") -> 898.17391 | E19: =AVERAGEIFS(Dati_Case!$E$2:$E$1061,Dati_Case!$A$2:$A$1061,$A19,Dati_Case!$D$2:$D$1061,"Isole") -> 944.30769
A20: 2019 | B20: =AVERAGEIFS(Dati_Case!$E$2:$E$1061,Dati_Case!$A$2:$A$1061,$A20,Dati_Case!$D$2:$D$1061,"Nord") -> 1438 | C20: =AVERAGEIFS(Dati_Case!$E$2:$E$1061,Dati_Case!$A$2:$A$1061,$A20,Dati_Case!$D$2:$D$1061,"Centro") -> 1485.0455 | D20: =AVERAGEIFS(Dati_Case!$E$2:$E$1061,Dati_Case!$A$2:$A$1061,$A20,Dati_Case!$D$2:$D$1061,"Sud") -> 903.54167 | E20: =AVERAGEIFS(Dati_Case!$E$2:$E$1061,Dati_Case!$A$2:$A$1061,$A20,Dati_Case!$D$2:$D$1061,"Isole") -> 936.69231
A21: 2020 | B21: =AVERAGEIFS(Dati_Case!$E$2:$E$1061,Dati_Case!$A$2:$A$1061,$A21,Dati_Case!$D$2:$D$1061,"Nord") -> 1433.9362 | C21: =AVERAGEIFS(Dati_Case!$E$2:$E$1061,Dati_Case!$A$2:$A$1061,$A21,Dati_Case!$D$2:$D$1061,"Centro") -> 1466.6818 | D21: =AVERAGEIFS(Dati_Case!$E$2:$E$1061,Dati_Case!$A$2:$A$1061,$A21,Dati_Case!$D$2:$D$1061,"Sud") -> 885.41667 | E21: =AVERAGEIFS(Dati_Case!$E$2:$E$1061,Dati_Case!$A$2:$A$1061,$A21,Dati_Case!$D$2:$D$1061,"Isole") -> 926.61538
A22: 2021 | B22: =AVERAGEIFS(Dati_Case!$E$2:$E$1061,Dati_Case!$A$2:$A$1061,$A22,Dati_Case!$D$2:$D$1061,"Nord") -> 1423.3191 | C22: =AVERAGEIFS(Dati_Case!$E$2:$E$1061,Dati_Case!$A$2:$A$1061,$A22,Dati_Case!$D$2:$D$1061,"Centro") -> 1440.3636 | D22: =AVERAGEIFS(Dati_Case!$E$2:$E$1061,Dati_Case!$A$2:$A$1061,$A22,Dati_Case!$D$2:$D$1061,"Sud") -> 874.04167 | E22: =AVERAGEIFS(Dati_Case!$E$2:$E$1061,Dati_Case!$A$2:$A$1061,$A22,Dati_Case!$D$2:$D$1061,"Isole") -> 907.92308
A23: 2022 | B23: =AVERAGEIFS(Dati_Case!$E$2:$E$1061,Dati_Case!$A$2:$A$1061,$A23,Dati_Case!$D$2:$D$1061,"Nord") -> 1434.1915 | C23: =AVERAGEIFS(Dati_Case!$E$2:$E$1061,Dati_Case!$A$2:$A$1061,$A23,Dati_Case!$D$2:$D$1061,"Centro") -> 1431.6818 | D23: =AVERAGEIFS(Dati_Case!$E$2:$E$1061,Dati_Case!$A$2:$A$1061,$A23,Dati_Case!$D$2:$D$1061,"Sud") -> 872.45833 | E23: =AVERAGEIFS(Dati_Case!$E$2:$E$1061,Dati_Case!$A$2:$A$1061,$A23,Dati_Case!$D$2:$D$1061,"Isole") -> 902.38462
A24: 2023 | B24: =AVERAGEIFS(Dati_Case!$E$2:$E$1061,Dati_Case!$A$2:$A$1061,$A24,Dati_Case!$D$2:$D$1061,"Nord") -> 1449.8511 | C24: =AVERAGEIFS(Dati_Case!$E$2:$E$1061,Dati_Case!$A$2:$A$1061,$A24,Dati_Case!$D$2:$D$1061,"Centro") -> 1434.5909 | D24: =AVERAGEIFS(Dati_Case!$E$2:$E$1061,Dati_Case!$A$2:$A$1061,$A24,Dati_Case!$D$2:$D$1061,"Sud") -> 876.875 | E24: =AVERAGEIFS(Dati_Case!$E$2:$E$1061,Dati_Case!$A$2:$A$1061,$A24,Dati_Case!$D$2:$D$1061,"Isole") -> 904.92308
A25: 2024 | B25: =AVERAGEIFS(Dati_Case!$E$2:$E$1061,Dati_Case!$A$2:$A$1061,$A25,Dati_Case!$D$2:$D$1061,"Nord") -> 1467.383 | C25: =AVERAGEIFS(Dati_Case!$E$2:$E$1061,Dati_Case!$A$2:$A$1061,$A25,Dati_Case!$D$2:$D$1061,"Centro") -> 1436.0455 | D25: =AVERAGEIFS(Dati_Case!$E$2:$E$1061,Dati_Case!$A$2:$A$1061,$A25,Dati_Case!$D$2:$D$1061,"Sud") -> 884.625 | E25: =AVERAGEIFS(Dati_Case!$E$2:$E$1061,Dati_Case!$A$2:$A$1061,$A25,Dati_Case!$D$2:$D$1061,"Isole") -> 908.92308
A26: 2025 | B26: =AVERAGEIFS(Dati_Case!$E$2:$E$1061,Dati_Case!$A$2:$A$1061,$A26,Dati_Case!$D$2:$D$1061,"Nord") -> 1496.2979 | C26: =AVERAGEIFS(Dati_Case!$E$2:$E$1061,Dati_Case!$A$2:$A$1061,$A26,Dati_Case!$D$2:$D$1061,"Centro") -> 1442.8636 | D26: =AVERAGEIFS(Dati_Case!$E$2:$E$1061,Dati_Case!$A$2:$A$1061,$A26,Dati_Case!$D$2:$D$1061,"Sud") -> 890.375 | E26: =AVERAGEIFS(Dati_Case!$E$2:$E$1061,Dati_Case!$A$2:$A$1061,$A26,Dati_Case!$D$2:$D$1061,"Isole") -> 921.23077

Sheet Dati_Redditi
A1: anno | B1: sigla | C1: provincia | D1: zona | E1: contribuenti | F1: reddito_medio | G1: stipendio_medio | H1: pensione_media
A2: 2016 | B2: AG | C2: Agrigento | D2: Isole | E2: 252923 | F2: 14386 | G2: 15623 | H2: 12534
A3: 2016 | B3: AL | C3: Alessandria | D3: Nord | E3: 310619 | F3: 21243 | G3: 21358 | H3: 17126
A4: 2016 | B4: AN | C4: Ancona | D4: Centro | E4: 344679 | F4: 21104 | G4: 20308 | H4: 17386
A5: 2016 | B5: AO | C5: Aosta | D5: Nord | E5: 96833 | F5: 22285 | G5: 20531 | H5: 17462
A6: 2016 | B6: AP | C6: Ascoli Piceno | D6: Centro | E6: 149359 | F6: 18497 | G6: 18249 | H6: 15582
A7: 2016 | B7: AQ | C7: L'Aquila | D7: Sud | E7: 209304 | F7: 18553 | G7: 18786 | H7: 16078
A8: 2016 | B8: AR | C8: Arezzo | D8: Centro | E8: 252116 | F8: 20354 | G8: 19360 | H8: 16577
A9: 2016 | B9: AT | C9: Asti | D9: Nord | E9: 157366 | F9: 20415 | G9: 20278 | H9: 16474
A10: 2016 | B10: AV | C10: Avellino | D10: Sud | E10: 264376 | F10: 16030 | G10: 17173 | H10: 13574
A11: 2016 | B11: BA | C11: Bari | D11: Sud | E11: 798662 | F11: 17752 | G11: 17551 | H11: 16407
A12: 2016 | B12: BG | C12: Bergamo | D12: Nord | E12: 773580 | F12: 22942 | G12: 22909 | H12: 17255
A13: 2016 | B13: BI | C13: Biella | D13: Nord | E13: 135459 | F13: 21524 | G13: 21860 | H13: 17199
... A963: 2024 | B963: VV | C963: Vibo Valentia | D963: Sud | E963: 99473 | F963: 17913 | G963: 16880 | H963: 17488

Sheet Dati_Case
A1: anno | B1: sigla | C1: provincia | D1: zona | E1: prezzo_mq
A2: 2016 | B2: AG | C2: Agrigento | D2: Isole | E2: 662
A3: 2017 | B3: AG | C3: Agrigento | D3: Isole | E3: 641
A4: 2018 | B4: AG | C4: Agrigento | D4: Isole | E4: 639
A5: 2019 | B5: AG | C5: Agrigento | D5: Isole | E5: 631
A6: 2020 | B6: AG | C6: Agrigento | D6: Isole | E6: 617
A7: 2021 | B7: AG | C7: Agrigento | D7: Isole | E7: 594
A8: 2022 | B8: AG | C8: Agrigento | D8: Isole | E8: 583
A9: 2023 | B9: AG | C9: Agrigento | D9: Isole | E9: 582
A10: 2024 | B10: AG | C10: Agrigento | D10: Isole | E10: 576
A11: 2025 | B11: AG | C11: Agrigento | D11: Isole | E11: 581
A12: 2016 | B12: AL | C12: Alessandria | D12: Nord | E12: 894
A13: 2017 | B13: AL | C13: Alessandria | D13: Nord | E13: 890
... A171: 2025 | B171: BS | C171: Brescia | D171: Nord | E171: 1548
A172: 2016 | B172: BT | C172: Barletta-Andria-Trani | D172: Sud
A173: 2017 | B173: BT | C173: Barletta-Andria-Trani | D173: Sud
A174: 2018 | B174: BT | C174: Barletta-Andria-Trani | D174: Sud
A175: 2019 | B175: BT | C175: Barletta-Andria-Trani | D175: Sud | E175: 1209
A176: 2020 | B176: BT | C176: Barletta-Andria-Trani | D176: Sud | E176: 1201
A177: 2021 | B177: BT | C177: Barletta-Andria-Trani | D177: Sud | E177: 1198
A178: 2022 | B178: BT | C178: Barletta-Andria-Trani | D178: Sud | E178: 1196
A179: 2023 | B179: BT | C179: Barletta-Andria-Trani | D179: Sud | E179: 1203
A180: 2024 | B180: BT | C180: Barletta-Andria-Trani | D180: Sud | E180: 1210
A181: 2025 | B181: BT | C181: Barletta-Andria-Trani | D181: Sud | E181: 1217
A182: 2016 | B182: BZ | C182: Bolzano | D182: Nord | E182: 2810
A183: 2017 | B183: BZ | C183: Bolzano | D183: Nord | E183: 2827
A184: 2018 | B184: BZ | C184: Bolzano | D184: Nord | E184: 2859
A185: 2019 | B185: BZ | C185: Bolzano | D185: Nord | E185: 2868
A186: 2020 | B186: BZ | C186: Bolzano | D186: Nord | E186: 2878
... A991: 2025 | B991: VA | C991: Varese | D991: Nord | E991: 1391
A992: 2016 | B992: VB | C992: Verbano-Cusio-Ossola | D992: Nord
A993: 2017 | B993: VB | C993: Verbano-Cusio-Ossola | D993: Nord | E993: 1287
A994: 2018 | B994: VB | C994: Verbano-Cusio-Ossola | D994: Nord | E994: 1280
A995: 2019 | B995: VB | C995: Verbano-Cusio-Ossola | D995: Nord | E995: 1277
A996: 2020 | B996: VB | C996: Verbano-Cusio-Ossola | D996: Nord | E996: 1271
A997: 2021 | B997: VB | C997: Verbano-Cusio-Ossola | D997: Nord | E997: 1243
A998: 2022 | B998: VB | C998: Verbano-Cusio-Ossola | D998: Nord | E998: 1238
A999: 2023 | B999: VB | C999: Verbano-Cusio-Ossola | D999: Nord | E999: 1250
A1000: 2024 | B1000: VB | C1000: Verbano-Cusio-Ossola | D1000: Nord | E1000: 1263
A1001: 2025 | B1001: VB | C1001: Verbano-Cusio-Ossola | D1001: Nord | E1001: 1275
...
